show ip int brief
show version
show tech

[1m[36msend_commands_test**************************************************************[0m
[0m[1m[34m* R1 ** changed : False ********************************************************[0m
[0m[1m[31mvvvv send_commands_test ** changed : False vvvvvvvvvvvvvvvvvvvvvvvvvvvvvvvvvvvvv ERROR[0m
[0mSubtask: send_commands (failed)
[0m
[0m[1m[31m---- send_commands ** changed : False ------------------------------------------ ERROR[0m
[0mTraceback (most recent call last):
  File "/home/auto/karan/.venv/lib/python3.12/site-packages/nornir/core/task.py", line 99, in start
    r = self.task(self, **self.params)
        ^^^^^^^^^^^^^^^^^^^^^^^^^^^^^^
  File "/home/auto/karan/.venv/lib/python3.12/site-packages/nornir_scrapli/tasks/core/send_commands.py", line 44, in send_commands
    scrapli_conn = task.host.get_connection("scrapli", task.nornir.config)
                   ^^^^^^^^^^^^^^^^^^^^^^^^^^^^^^^^^^^^^^^^^^^^^^^^^^^^^^^
  File "/home/auto/karan/.venv/lib/python3.12/site-packages/nornir/core/inventory.py", line 494, in get_connection
    self.open_connection(
  File "/home/auto/karan/.venv/lib/python3.12/site-packages/nornir/core/inventory.py", line 546, in open_connection
    conn_obj.open(
  File "/home/auto/karan/.venv/lib/python3.12/site-packages/nornir_scrapli/connection.py", line 106, in open
    connection.open()
  File "/home/auto/karan/.venv/lib/python3.12/site-packages/scrapli/driver/base/sync_driver.py", line 106, in open
    self.channel.channel_authenticate_ssh(
  File "/home/auto/karan/.venv/lib/python3.12/site-packages/scrapli/decorators.py", line 224, in decorate
    return _multiprocessing_timeout(
           ^^^^^^^^^^^^^^^^^^^^^^^^^
  File "/home/auto/karan/.venv/lib/python3.12/site-packages/scrapli/decorators.py", line 115, in _multiprocessing_timeout
    return future.result()
           ^^^^^^^^^^^^^^^
  File "/usr/lib/python3.12/concurrent/futures/_base.py", line 449, in result
    return self.__get_result()
           ^^^^^^^^^^^^^^^^^^^
  File "/usr/lib/python3.12/concurrent/futures/_base.py", line 401, in __get_result
    raise self._exception
  File "/usr/lib/python3.12/concurrent/futures/thread.py", line 58, in run
    result = self.fn(*self.args, **self.kwargs)
             ^^^^^^^^^^^^^^^^^^^^^^^^^^^^^^^^^^
  File "/home/auto/karan/.venv/lib/python3.12/site-packages/scrapli/channel/sync_channel.py", line 297, in channel_authenticate_ssh
    self._ssh_message_handler(output=authenticate_buf)
  File "/home/auto/karan/.venv/lib/python3.12/site-packages/scrapli/channel/base_channel.py", line 481, in _ssh_message_handler
    raise ScrapliAuthenticationFailed(msg)
scrapli.exceptions.ScrapliAuthenticationFailed: No route to host
[0m
[0m[1m[31m^^^^ END send_commands_test ^^^^^^^^^^^^^^^^^^^^^^^^^^^^^^^^^^^^^^^^^^^^^^^^^^^^[0m
[0m[1m[34m* R2 ** changed : False ********************************************************[0m
[0m[1m[31mvvvv send_commands_test ** changed : False vvvvvvvvvvvvvvvvvvvvvvvvvvvvvvvvvvvvv ERROR[0m
[0mSubtask: send_commands (failed)
[0m
[0m[1m[31m---- send_commands ** changed : False ------------------------------------------ ERROR[0m
[0mTraceback (most recent call last):
  File "/home/auto/karan/.venv/lib/python3.12/site-packages/nornir/core/task.py", line 99, in start
    r = self.task(self, **self.params)
        ^^^^^^^^^^^^^^^^^^^^^^^^^^^^^^
  File "/home/auto/karan/.venv/lib/python3.12/site-packages/nornir_scrapli/tasks/core/send_commands.py", line 44, in send_commands
    scrapli_conn = task.host.get_connection("scrapli", task.nornir.config)
                   ^^^^^^^^^^^^^^^^^^^^^^^^^^^^^^^^^^^^^^^^^^^^^^^^^^^^^^^
  File "/home/auto/karan/.venv/lib/python3.12/site-packages/nornir/core/inventory.py", line 494, in get_connection
    self.open_connection(
  File "/home/auto/karan/.venv/lib/python3.12/site-packages/nornir/core/inventory.py", line 546, in open_connection
    conn_obj.open(
  File "/home/auto/karan/.venv/lib/python3.12/site-packages/nornir_scrapli/connection.py", line 106, in open
    connection.open()
  File "/home/auto/karan/.venv/lib/python3.12/site-packages/scrapli/driver/base/sync_driver.py", line 106, in open
    self.channel.channel_authenticate_ssh(
  File "/home/auto/karan/.venv/lib/python3.12/site-packages/scrapli/decorators.py", line 224, in decorate
    return _multiprocessing_timeout(
           ^^^^^^^^^^^^^^^^^^^^^^^^^
  File "/home/auto/karan/.venv/lib/python3.12/site-packages/scrapli/decorators.py", line 115, in _multiprocessing_timeout
    return future.result()
           ^^^^^^^^^^^^^^^
  File "/usr/lib/python3.12/concurrent/futures/_base.py", line 449, in result
    return self.__get_result()
           ^^^^^^^^^^^^^^^^^^^
  File "/usr/lib/python3.12/concurrent/futures/_base.py", line 401, in __get_result
    raise self._exception
  File "/usr/lib/python3.12/concurrent/futures/thread.py", line 58, in run
    result = self.fn(*self.args, **self.kwargs)
             ^^^^^^^^^^^^^^^^^^^^^^^^^^^^^^^^^^
  File "/home/auto/karan/.venv/lib/python3.12/site-packages/scrapli/channel/sync_channel.py", line 297, in channel_authenticate_ssh
    self._ssh_message_handler(output=authenticate_buf)
  File "/home/auto/karan/.venv/lib/python3.12/site-packages/scrapli/channel/base_channel.py", line 481, in _ssh_message_handler
    raise ScrapliAuthenticationFailed(msg)
scrapli.exceptions.ScrapliAuthenticationFailed: No route to host
[0m
[0m[1m[31m^^^^ END send_commands_test ^^^^^^^^^^^^^^^^^^^^^^^^^^^^^^^^^^^^^^^^^^^^^^^^^^^^[0m
[0m[1m[34m* R3 ** changed : False ********************************************************[0m
[0m[1m[31mvvvv send_commands_test ** changed : False vvvvvvvvvvvvvvvvvvvvvvvvvvvvvvvvvvvvv ERROR[0m
[0mSubtask: send_commands (failed)
[0m
[0m[1m[31m---- send_commands ** changed : False ------------------------------------------ ERROR[0m
[0mTraceback (most recent call last):
  File "/home/auto/karan/.venv/lib/python3.12/site-packages/nornir/core/task.py", line 99, in start
    r = self.task(self, **self.params)
        ^^^^^^^^^^^^^^^^^^^^^^^^^^^^^^
  File "/home/auto/karan/.venv/lib/python3.12/site-packages/nornir_scrapli/tasks/core/send_commands.py", line 44, in send_commands
    scrapli_conn = task.host.get_connection("scrapli", task.nornir.config)
                   ^^^^^^^^^^^^^^^^^^^^^^^^^^^^^^^^^^^^^^^^^^^^^^^^^^^^^^^
  File "/home/auto/karan/.venv/lib/python3.12/site-packages/nornir/core/inventory.py", line 494, in get_connection
    self.open_connection(
  File "/home/auto/karan/.venv/lib/python3.12/site-packages/nornir/core/inventory.py", line 546, in open_connection
    conn_obj.open(
  File "/home/auto/karan/.venv/lib/python3.12/site-packages/nornir_scrapli/connection.py", line 106, in open
    connection.open()
  File "/home/auto/karan/.venv/lib/python3.12/site-packages/scrapli/driver/base/sync_driver.py", line 106, in open
    self.channel.channel_authenticate_ssh(
  File "/home/auto/karan/.venv/lib/python3.12/site-packages/scrapli/decorators.py", line 224, in decorate
    return _multiprocessing_timeout(
           ^^^^^^^^^^^^^^^^^^^^^^^^^
  File "/home/auto/karan/.venv/lib/python3.12/site-packages/scrapli/decorators.py", line 115, in _multiprocessing_timeout
    return future.result()
           ^^^^^^^^^^^^^^^
  File "/usr/lib/python3.12/concurrent/futures/_base.py", line 449, in result
    return self.__get_result()
           ^^^^^^^^^^^^^^^^^^^
  File "/usr/lib/python3.12/concurrent/futures/_base.py", line 401, in __get_result
    raise self._exception
  File "/usr/lib/python3.12/concurrent/futures/thread.py", line 58, in run
    result = self.fn(*self.args, **self.kwargs)
             ^^^^^^^^^^^^^^^^^^^^^^^^^^^^^^^^^^
  File "/home/auto/karan/.venv/lib/python3.12/site-packages/scrapli/channel/sync_channel.py", line 297, in channel_authenticate_ssh
    self._ssh_message_handler(output=authenticate_buf)
  File "/home/auto/karan/.venv/lib/python3.12/site-packages/scrapli/channel/base_channel.py", line 481, in _ssh_message_handler
    raise ScrapliAuthenticationFailed(msg)
scrapli.exceptions.ScrapliAuthenticationFailed: No route to host
[0m
[0m[1m[31m^^^^ END send_commands_test ^^^^^^^^^^^^^^^^^^^^^^^^^^^^^^^^^^^^^^^^^^^^^^^^^^^^[0m
[0m[1m[34m* R4 ** changed : False ********************************************************[0m
[0m[1m[31mvvvv send_commands_test ** changed : False vvvvvvvvvvvvvvvvvvvvvvvvvvvvvvvvvvvvv ERROR[0m
[0mSubtask: send_commands (failed)
[0m
[0m[1m[31m---- send_commands ** changed : False ------------------------------------------ ERROR[0m
[0mTraceback (most recent call last):
  File "/home/auto/karan/.venv/lib/python3.12/site-packages/nornir/core/task.py", line 99, in start
    r = self.task(self, **self.params)
        ^^^^^^^^^^^^^^^^^^^^^^^^^^^^^^
  File "/home/auto/karan/.venv/lib/python3.12/site-packages/nornir_scrapli/tasks/core/send_commands.py", line 44, in send_commands
    scrapli_conn = task.host.get_connection("scrapli", task.nornir.config)
                   ^^^^^^^^^^^^^^^^^^^^^^^^^^^^^^^^^^^^^^^^^^^^^^^^^^^^^^^
  File "/home/auto/karan/.venv/lib/python3.12/site-packages/nornir/core/inventory.py", line 494, in get_connection
    self.open_connection(
  File "/home/auto/karan/.venv/lib/python3.12/site-packages/nornir/core/inventory.py", line 546, in open_connection
    conn_obj.open(
  File "/home/auto/karan/.venv/lib/python3.12/site-packages/nornir_scrapli/connection.py", line 106, in open
    connection.open()
  File "/home/auto/karan/.venv/lib/python3.12/site-packages/scrapli/driver/base/sync_driver.py", line 106, in open
    self.channel.channel_authenticate_ssh(
  File "/home/auto/karan/.venv/lib/python3.12/site-packages/scrapli/decorators.py", line 224, in decorate
    return _multiprocessing_timeout(
           ^^^^^^^^^^^^^^^^^^^^^^^^^
  File "/home/auto/karan/.venv/lib/python3.12/site-packages/scrapli/decorators.py", line 115, in _multiprocessing_timeout
    return future.result()
           ^^^^^^^^^^^^^^^
  File "/usr/lib/python3.12/concurrent/futures/_base.py", line 449, in result
    return self.__get_result()
           ^^^^^^^^^^^^^^^^^^^
  File "/usr/lib/python3.12/concurrent/futures/_base.py", line 401, in __get_result
    raise self._exception
  File "/usr/lib/python3.12/concurrent/futures/thread.py", line 58, in run
    result = self.fn(*self.args, **self.kwargs)
             ^^^^^^^^^^^^^^^^^^^^^^^^^^^^^^^^^^
  File "/home/auto/karan/.venv/lib/python3.12/site-packages/scrapli/channel/sync_channel.py", line 297, in channel_authenticate_ssh
    self._ssh_message_handler(output=authenticate_buf)
  File "/home/auto/karan/.venv/lib/python3.12/site-packages/scrapli/channel/base_channel.py", line 481, in _ssh_message_handler
    raise ScrapliAuthenticationFailed(msg)
scrapli.exceptions.ScrapliAuthenticationFailed: No route to host
[0m
[0m[1m[31m^^^^ END send_commands_test ^^^^^^^^^^^^^^^^^^^^^^^^^^^^^^^^^^^^^^^^^^^^^^^^^^^^[0m
[0m